Workbook
Name Abies_alba: All_LTMN_Lookups!$J$2:$J$1223
Name Abies_alba: #REF!
Name Abies_alba: #REF!
Name ALLQCODETYPES: '[1]NEW QCODES'!#REF!
Name AllSC: #REF!
Name AllSC: #REF!
Name B01_: [2]All_LTMN_Lookups!$I$2:$I$41
Name Broad_habitat: [2]All_LTMN_Lookups!$N$2:$N$18
Name BROADHAB: #REF!
Name BROADHAB: #REF!
Name C_: [3]All_LTMN_Lookups!$C$2:$C$8
Name D1VW: 'Dominance Template'!$A$1:$G$1
Name D2VW: 'Seedlings Template'!$A$1:$P$2
Name D3VC: #REF!
Name D3VW: 'Tree Measurement'!$A$1:$W$1
Name DESC_LATIN: 'Species Template'!#REF!
Name DESC_LATIN: 'Species Template'!#REF!
Name DI: #REF!
Name DI: #REF!
Name DOMCODE: #REF!
Name DOMCODE: #REF!
Name ENVIROCODES: #REF!
Name ENVIROCODES: #REF!
Name INVERTCODES: #REF!
Name INVERTCODES: #REF!
Name LANDUSE: #REF!
Name LANDUSE: #REF!
Name Latin: #REF!
Name Latin: #REF!
Name MCODE: #REF!
Name MCODE: #REF!
Name OTHERSCODES: #REF!
Name OTHERSCODES: #REF!
Name PRIHAB: #REF!
Name PRIHAB: #REF!
Name PriorityHabitat: [2]All_LTMN_Lookups!$O$2:$O$34
Name Q_code: [4]All_LTMN_Lookups!$L$2:$L$140
Name QA: #REF!
Name QA: All_LTMN_Lookups!$V$2:$V$27
Name qcode: [2]All_LTMN_Lookups!$L$2:$L$140
Name qtext: [2]All_LTMN_Lookups!$M$2:$M$140
Name Site_code: All_LTMN_Lookups!#REF!
Name Site_code: [5]All_LTMN_Lookups!$I$2:$I$41
Name Site_code: [5]All_LTMN_Lookups!$I$2:$I$41
Name Site_code: #REF!
Name sitecode: [5]All_LTMN_Lookups!$I$2:$I$41
Name sitecode: [6]All_LTMN_Lookups!$I$2:$I$41
Name sitecode: [5]All_LTMN_Lookups!$I$2:$I$41
Name SITECODES: #REF!
Name SITECODES: #REF!
Name SLOPEFORM: #REF!
Name SLOPEFORM: #REF!
Name TEMP_LIST: 'Species Template'!#REF!
Name TEMP_LIST: 'Species Template'!#REF!
Name vcode: #REF!
Name vcode: #REF!
Name vcode: #REF!
Name vcode: #REF!
Name vecode: #REF!
Name vecode: #REF!

Sheet Home
B2: Long Term Monitoring Network Vegetation Survey
B4: Site | C4: Thursley
B6: Year | C6: 2015
B8: Creator
B10: Organisation
B12: Additional Information
B14: All methodologies for the data collection, processing and quality assurance can be found here:
B16: LTMN@ Access to Evidence Catalogue
B18: Units for measurements can be found below:
B20: Sheet | C20: Field | D20: Unit
B21: Whole Plot Data | C21: ALTITUDE | D21: Metres
B22: Ground Features | C22: VEG_HEIGHT | D22: Centimetres
B23: Tree Measurement | C23: GIRTH | D23: Centimetres
B24: Tree Measurement | C24: HEIGHT | D24: Metres
B25: Tree Measurement | C25: DISTANCE | D25: Metres
B26: Tree Measurement | C26: SURVEYOR_HEIGHT | D26: Metres
B27: Tree Measurement | C27: ANGLE | D27: Degrees
B29: Survey Notes:
B30: Second survey on this site. Plots surveyed: 49, of which 3 woodland. Species richness: 102. Cladonia strepsilis also identified on site, but not within a plot. Screened for sensitive species and one line of data removed from the Species Template - please contact Natural England if you need the removed data.
B34: Change log:
B36: 43572 | C36: Document created
B37: 43635 | C37: Checked and QA'd
B38: 43740 | C38: Vegetation heights added
B39: 43810 | C39: Plots 3, 8, 11, 12, 14, 37, 38, 53, 59 had been renamed plots 76-84 on the Whole Plot Data tab only. Returned them to original names.

Sheet Whole Plot Data
A1: SITECODE | B1: MCODE | C1: YEAR | D1: PLOT_ID | E1: STRAT | F1: EASTINGS | G1: NORTHINGS | H1: BNG_GRID_REF | I1: SURVEYOR | J1: SDATE | K1: ALTITUDE | L1: LANDUSE_CODE | M1: SLOPE | N1: ASPECT | O1: SLOPEFORM_CODE | P1: NVCCLASS | Q1: NVC_FIRST | R1: NVC_SECOND | S1: NVC_THIRD | T1: LIGHT | U1: WETNESS | V1: PH | W1: FERTILITY | X1: COMPETITION | Y1: STRESS | Z1: RUDERALS | AA1: SCODE1 | AB1: SCODE2 | AC1: SCODE3 | AD1: FIELD_SHEET_NOTES | AE1: BAP_BROAD | AF1: BAP_PRIORITY | AG1: DATA_ENTRY_COMMENTS | AH1: DATA_ISSUE1 | AI1: DATA_ISSUE2 | AJ1: DATA_ISSUE3 | AK1: QA_CODE1 | AL1: QA_CODE2 | AM1: QA_CODE3 | AN1: FINAL_QA | AO1: LOCATION_REMARK
A2: B26 | B2: VC | C2: 2015 | D2: 2 | E2: NNR Site Boundary (Heathland) | F2: 490420.95 | G2: 141359.26 | H2: SU9042041359 | J2: 42213 | K2: 67 | L2: 14 | M2: 10 | N2: 270 | O2: 2 | Q2: H8a:34.88 | R2: H2:33.29 | S2: H2b:31.14 | T2: 6.9 | U2: 5.3 | V2: 2.1 | W2: 2.1 | X2: 2.74 | Y2: 3.26 | Z2: 1 | AA2: 144 | AE2: Dwarf Shrub Heath | AF2: Lowland Heathland
A3: B26 | B3: VC | C3: 2015 | D3: 3 | E3: NNR Site Boundary (Heathland) | F3: 490929.17 | G3: 140855.85 | H3: SU9092940855 | J3: 42213 | K3: 77 | L3: 14 | M3: 8 | N3: 6 | O3: 2 | Q3: H2a:46.68 | R3: H2:45.10 | S3: W18a:44.76 | T3: 6.6 | U3: 5.1 | V3: 2.1 | W3: 2.4 | X3: 2.06 | Y3: 3.94 | Z3: 1.02 | AA3: 144 | AD3: rabbit poo. | AE3: Dwarf Shrub Heath | AF3: Lowland Heathland
A4: B26 | B4: VC | C4: 2015 | D4: 6 | E4: NNR Site Boundary (Heathland) | F4: 490396.94 | G4: 141506.75 | H4: SU9039641506 | J4: 42213 | K4: 60 | L4: 18 | M4: 0 | O4: 2 | Q4: M21:70.57 | R4: M21b:65.73 | S4: M21a:64.62 | T4: 7.7 | U4: 8.3 | V4: 2.5 | W4: 1.3 | X4: 2.47 | Y4: 3.53 | Z4: 1 | AE4: Fen, Marsh and Swamp | AF4: Lowland Fens | AG4: Aspect not recorded. Query target habitat. BAP_PRIORITY not recorded. | AH4: DI900 | AI4: DI990
A5: B26 | B5: VC | C5: 2015 | D5: 7 | E5: NNR Site Boundary (Heathland) | F5: 490500.39 | G5: 141240.6 | H5: SU9050041240 | J5: 42213 | K5: 66 | L5: 14 | M5: 9 | N5: 45 | O5: 3 | Q5: H2:49.04 | R5: H2a:48.55 | S5: H2b:44.76 | T5: 6.9 | U5: 5.4 | V5: 2.2 | W5: 2.2 | X5: 2.83 | Y5: 3.17 | Z5: 1 | AE5: Dwarf Shrub Heath | AF5: Lowland Heathland
A6: B26 | B6: VC | C6: 2015 | D6: 8 | E6: Lowland Mire & Fens | F6: 491335 | G6: 140037 | H6: SU9133540037 | J6: 42214 | K6: 91 | L6: 14 | M6: 14 | N6: 54 | O6: 1 | Q6: H2a:46.45 | R6: H2:42.91 | S6: H8a:38.46 | T6: 7 | U6: 5.2 | V6: 2 | W6: 2 | X6: 2.17 | Y6: 3.83 | Z6: 1 | AD6: Scrubbing up with birch (B. pendula. | AE6: Dwarf Shrub Heath | AF6: Lowland Heathland
A7: B26 | B7: VC | C7: 2015 | D7: 11 | E7: Lowland Mire & Fens | F7: 491475.74 | G7: 141051.47 | H7: SU9147541051 | J7: 42214 | K7: 61 | L7: 14 | M7: 2 | N7: 340 | O7: 2 | Q7: H2a:34.31 | R7: H1b:32.30 | S7: H2:31.50 | T7: 7 | U7: 5.9 | V7: 2.2 | W7: 2.2 | X7: 3.11 | Y7: 2.89 | Z7: 1 | AA7: 144 | AD7: rabbit droppings | AE7: Dwarf Shrub Heath | AF7: Lowland Heathland
A8: B26 | B8: VC | C8: 2015 | D8: 12 | E8: Lowland Mire & Fens | F8: 491349.79 | G8: 140471 | H8: SU9134940470 | J8: 42214 | K8: 65 | L8: 14 | M8: 5 | N8: 150 | O8: 1 | Q8: U20b:53.91 | R8: U20c:47.00 | S8: H1c:46.97 | T8: 6.6 | U8: 5.1 | V8: 2.5 | W8: 2.4 | X8: 2.97 | Y8: 3.02 | Z8: 1.02 | AA8: 144 | AD8: rabbit | AE8: bracken | AF8: Not a priority habitat
A9: B26 | B9: VC | C9: 2015 | D9: 13 | E9: NNR Site Boundary (Heathland) | F9: 490075.93 | G9: 140775.23 | H9: SU9007540775 | J9: 42213 | K9: 66 | L9: 14 | M9: 7 | O9: 2 | Q9: H1e:26.18 | R9: H1:25.24 | S9: H11c:24.92 | T9: 7 | U9: 6 | V9: 2 | W9: 2 | X9: 3 | Y9: 3 | Z9: 1 | AA9: 144 | AB9: 115 | AE9: Dwarf Shrub Heath | AF9: Lowland Heathland | AG9: Aspect not recorded, BAP_BROAD not recorded. | AH9: DI900 | AI9: DI990
A10: B26 | B10: VC | C10: 2015 | D10: 14 | E10: NNR Site Boundary (Heathland) | F10: 490017.31 | G10: 140297.7 | H10: SU9001740297 | J10: 42214 | K10: 71 | L10: 13 | M10: 16 | N10: 34 | O10: 3 | Q10: W4:21.43 | R10: W16a:20.12 | S10: W10d:20.00 | T10: 6.9 | U10: 5.4 | V10: 4.7 | W10: 3.3 | X10: 3.26 | Y10: 2.74 | Z10: 1 | AE10: Broadleaved, Mixed and Yew Woodland | AF10: Wet Woodland
A11: B26 | B11: VC | C11: 2015 | D11: 16 | E11: NNR Site Boundary (Heathland) | F11: 490268.49 | G11: 140824.11 | H11: SU9026840824 | J11: 42213 | K11: 67 | L11: 14 | M11: 5 | N11: 42 | O11: 2 | Q11: M21:47.22 | R11: M21b:45.85 | S11: M16a:43.96 | T11: 7.4 | U11: 8 | V11: 2.9 | W11: 1.7 | X11: 2.64 | Y11: 3.32 | Z11: 1.08 | AA11: 144 | AE11: Fen, Marsh and Swamp | AF11: Lowland Fens
A12: B26 | B12: VC | C12: 2015 | D12: 18 | E12: NNR Site Boundary (Heathland) | F12: 490656.45 | G12: 141298.92 | H12: SU9065641298 | J12: 42213 | K12: 60 | L12: 14 | M12: 2 | N12: 140 | O12: 3 | Q12: H2c:54.76 | R12: H2:51.22 | S12: H2a:50.91 | T12: 7.1 | U12: 6.5 | V12: 2.2 | W12: 2.1 | X12: 3.08 | Y12: 2.92 | Z12: 1 | AE12: Dwarf Shrub Heath | AF12: Lowland Heathland
A13: B26 | B13: VW | C13: 2015 | D13: 19 | E13: NNR Site Boundary (Heathland) | F13: 489865.24 | G13: 140737.24 | H13: SU8986540737 | I13: PLOT NOT SURVEYED THIS YEAR | J13: 42215 | AG13: PLOT NOT SURVEYED THIS YEAR.
A14: B26 | B14: VC | C14: 2015 | D14: 20 | E14: NNR Site Boundary (Heathland) | F14: 490477.18 | G14: 140979.79 | H14: SU9047740979 | J14: 42213 | K14: 0 | L14: 14 | M14: 10 | N14: 215 | O14: 1 | Q14: H2a:55.19 | R14: H2c:52.91 | S14: H2:50.00 | T14: 7.2 | U14: 5.6 | V14: 1.8 | W14: 2 | X14: 2.61 | Y14: 3.39 | Z14: 1 | AA14: 144 | AB14: 138 | AE14: Dwarf Shrub Heath | AF14: Lowland Heathland
A15: B26 | B15: VC | C15: 2015 | D15: 21 | E15: NNR Site Boundary (Heathland) | F15: 490190.43 | G15: 141470.67 | H15: SU9019041470 | J15: 42213 | K15: 57 | L15: 18 | M15: 0 | N15: 0 | O15: 2 | Q15: M21:66.21 | R15: M21b:66.20 | S15: M21a:57.04 | T15: 8 | U15: 8.6 | V15: 2.1 | W15: 1 | X15: 2.05 | Y15: 3.95 | Z15: 1 | AE15: Fen, Marsh and Swamp | AF15: Lowland Fens
A16: B26 | B16: VC | C16: 2015 | D16: 24 | E16: NNR Site Boundary (Heathland) | F16: 490865.84 | G16: 139855.75 | H16: SU9086539855 | J16: 42214 | K16: 105 | L16: 14 | M16: 6 | N16: 310 | O16: 2 | Q16: H9d:31.13 | R16: H12a:29.76 | S16: H2b:29.08 | T16: 6.5 | U16: 5.2 | V16: 2.3 | W16: 2.6 | X16: 2.06 | Y16: 3.93 | Z16: 1.29 | AE16: Dwarf Shrub Heath | AF16: Lowland Heathland
A17: B26 | B17: VC | C17: 2015 | D17: 25 | I17: PLOT NOT SURVEYED THIS YEAR | AG17: PLOT NOT SURVEYED THIS YEAR.
A18: B26 | B18: VC | C18: 2015 | D18: 26 | E18: NNR Site Boundary (Heathland) | F18: 491045.23 | G18: 140096.82 | H18: SU9104540096 | J18: 42214 | K18: 97 | L18: 14 | M18: 6 | N18: 148 | O18: 2 | Q18: H2a:44.02 | R18: H2:41.48 | S18: H2b:36.40 | T18: 7.5 | U18: 5.7 | V18: 1.6 | W18: 2 | X18: 2.68 | Y18: 3.32 | Z18: 1 | AA18: 144 | AE18: Dwarf Shrub Heath | AF18: Lowland Heathland | AG18: Question mark over plot number | AH18: DI990
A19: B26 | B19: VC | C19: 2015 | D19: 27 | E19: NNR Site Boundary (Heathland) | F19: 490741.5 | G19: 139985.94 | H19: SU9074139985 | J19: 42214 | K19: 102 | L19: 14 | M19: 6 | N19: 30 | O19: 2 | Q19: H2a:50.27 | R19: H2:46.99 | S19: H2b:42.97 | T19: 6.9 | U19: 5.2 | V19: 2 | W19: 2.2 | X19: 2.18 | Y19: 3.82 | Z19: 1.03 | AA19: 144 | AB19: 115 | AE19: Dwarf Shrub Heath | AF19: Lowland Heathland
A20: B26 | B20: VC | C20: 2015 | D20: 29 | E20: NNR Site Boundary (Heathland) | F20: 490263.56 | G20: 140144.12 | H20: SU9026340144 | J20: 42214 | K20: 97 | L20: 14 | M20: 5 | N20: 320 | O20: 2 | Q20: H2a:33.99 | R20: H2:31.36 | S20: H8a:30.64 | T20: 7 | U20: 5.7 | V20: 2 | W20: 2 | X20: 2.77 | Y20: 3.23 | Z20: 1 | AA20: 144 | AB20: 115 | AE20: Dwarf Shrub Heath | AF20: Lowland Heathland
A21: B26 | B21: VC | C21: 2015 | D21: 30 | E21: NNR Site Boundary (Heathland) | F21: 490597.35 | G21: 141428.34 | H21: SU9059741428 | J21: 42213 | K21: 58 | L21: 18 | M21: 0 | O21: 2 | Q21: M21:67.50 | R21: M21b:63.56 | S21: M21a:63.41 | T21: 7.9 | U21: 8.8 | V21: 2.1 | W21: 1.1 | X21: 2.25 | Y21: 3.75 | Z21: 1 | AE21: Fen, Marsh and Swamp | AF21: Lowland Fens | AG21: Aspect not recorded. BAP_PRIORITY not recorded. | AH21: DI900
A22: B26 | B22: VC | C22: 2015 | D22: 35 | E22: NNR Site Boundary (Heathland) | F22: 490120.77 | G22: 140065.83 | H22: SU9012040065 | J22: 42214 | K22: 89 | L22: 14 | M22: 3 | N22: 110 | O22: 2 | Q22: H1e:24.27 | R22: H1b:22.32 | S22: H1:21.37 | T22: 7 | U22: 6 | V22: 2 | W22: 2 | X22: 3 | Y22: 3 | Z22: 1.02 | AA22: 144 | AB22: 138 | AE22: Dwarf Shrub Heath | AF22: Lowland Heathland | AG22: BAP_PRIORITY not recorded. | AH22: DI900
A23: B26 | B23: VC | C23: 2015 | D23: 36 | E23: NNR Site Boundary (Heathland) | F23: 490473.74 | G23: 140157.13 | H23: SU9047340157 | J23: 42214 | K23: 92 | L23: 14 | M23: 2 | N23: 51 | O23: 1 | Q23: H2c:47.85 | R23: H2a:44.38 | S23: H2:43.78 | T23: 7.1 | U23: 5.3 | V23: 1.9 | W23: 2 | X23: 2.34 | Y23: 3.66 | Z23: 1 | AA23: 144 | AB23: 115 | AE23: Dwarf Shrub Heath | AF23: Lowland Heathland
A24: B26 | B24: VC | C24: 2015 | D24: 37 | E24: NNR Site Boundary (Heathland) | F24: 490330.41 | G24: 141312.29 | H24: SU9033041312 | J24: 42213 | K24: 59 | L24: 14 | M24: 1 | N24: 329 | O24: 3 | Q24: H2a:33.12 | R24: H2:32.63 | S24: H8a:29.81 | T24: 7 | U24: 5.8 | V24: 2.2 | W24: 2.2 | X24: 2.96 | Y24: 3.04 | Z24: 1 | AA24: 144 | AB24: 114 | AD24: very few rabbit droppings;burnt wood | AE24: Dwarf Shrub Heath | AF24: Lowland Heathland
A25: B26 | B25: VC | C25: 2015 | D25: 38 | E25: Lowland Mire & Fens | F25: 491469.76 | G25: 140904.12 | H25: SU9146940904 | J25: 42214 | K25: 57 | L25: 14 | M25: 0 | N25: 0 | O25: 2 | Q25: M15c:30.09 | R25: H2c:29.50 | S25: H4:26.97 | T25: 6.7 | U25: 6.3 | V25: 3 | W25: 2.6 | X25: 3.73 | Y25: 2.27 | Z25: 1.02 | AE25: Dwarf Shrub Heath | AF25: Lowland Heathland
A26: B26 | B26: VC | C26: 2015 | D26: 40 | E26: NNR Site Boundary (Heathland) | F26: 491050.28 | G26: 140348.21 | H26: SU9105040348 | J26: 42214 | K26: 87 | L26: 14 | M26: 15 | N26: 30 | O26: 2 | Q26: H2a:28.11 | R26: H1b:24.59 | S26: H2:24.27 | T26: 7 | U26: 6 | V26: 2 | W26: 2 | X26: 2.98 | Y26: 3.02 | Z26: 1 | AA26: 144 | AE26: Dwarf Shrub Heath | AF26: Lowland Heathland
A27: B26 | B27: VC | C27: 2015 | D27: 42 | E27: NNR Site Boundary (Heathland) | F27: 490207.88 | G27: 140239.09 | H27: SU9020740239 | J27: 42214 | K27: 95 | L27: 14 | M27: 0 | O27: 2 | Q27: H2a:34.99 | R27: H1b:32.56 | S27: H2:32.00 | T27: 7 | U27: 5.3 | V27: 2.1 | W27: 2.1 | X27: 2.4 | Y27: 3.6 | Z27: 1 | AA27: 144 | AB27: 115 | AE27: Dwarf Shrub Heath | AF27: Lowland Heathland | AG27: Aspect not recorded. | AH27: DI900
A28: B26 | B28: VC | C28: 2015 | D28: 44 | E28: NNR Site Boundary (Heathland) | F28: 490554.56 | G28: 139947.46 | H28: SU9055439947 | J28: 42214 | K28: 100 | L28: 14 | M28: 9 | N28: 10 | O28: 2 | Q28: H2:58.75 | R28: H2a:57.79 | S28: H2b:57.46 | T28: 7.1 | U28: 5.4 | V28: 2.2 | W28: 2.2 | X28: 2.6 | Y28: 3.4 | Z28: 1 | AA28: 143 | AB28: 115 | AE28: Dwarf Shrub Heath | AF28: Lowland Heathland | AG28: BAP_PRIORITY not recorded. | AH28: DI900
A29: B26 | B29: VW | C29: 2015 | D29: 45 | E29: NNR Site Boundary (Heathland) | F29: 489879.82 | G29: 141189.83 | H29: SU8987941189 | J29: 42215 | K29: 47 | L29: 14 | Q29: H12a:35.19 | R29: W18a:31.03 | S29: U2b:30.35 | T29: 6.7 | U29: 5 | V29: 4.1 | W29: 3 | X29: 2.71 | Y29: 3.29 | Z29: 1 | AA29: 144 | AE29: Broadleaved, Mixed and Yew Woodland | AF29: Lowland Mixed Deciduous Woodland | AG29: Slope, aspect & slopeform not recorded. Query target habitat. | AH29: DI900 | AI29: DI990
A30: B26 | B30: VC | C30: 2015 | D30: 46 | E30: NNR Site Boundary (Heathland) | F30: 490964.28 | G30: 140401.6 | H30: SU9096440401 | J30: 42213 | K30: 83 | L30: 14 | M30: 1 | N30: 110 | O30: 2 | Q30: H2a:38.50 | R30: H2:36.04 | S30: H3b:33.93 | T30: 7.1 | U30: 5.9 | V30: 1.9 | W30: 2 | X30: 2.93 | Y30: 3.07 | Z30: 1 | AB30: 551 | AE30: Dwarf Shrub Heath | AF30: Lowland Heathland
A31: B26 | B31: VC | C31: 2015 | D31: 48 | E31: NNR Site Boundary (Heathland) | F31: 490371.65 | G31: 140399.79 | H31: SU9037140399 | J31: 42213 | K31: 84 | L31: 14 | M31: 6 | N31: 334 | O31: 3 | Q31: H2a:43.10 | R31: H2c:37.09 | S31: H2:36.84 | T31: 7.2 | U31: 6 | V31: 1.8 | W31: 2 | X31: 2.99 | Y31: 3.01 | Z31: 1 | AA31: 144 | AB31: 138 | AE31: Dwarf Shrub Heath | AF31: Lowland Heathland | AG31: BAP_PRIORITY not recorded. | AH31: DI900
A32: B26 | B32: VC | C32: 2015 | D32: 49 | E32: NNR Site Boundary (Heathland) | F32: 490747.16 | G32: 140306.19 | H32: SU9074740306 | J32: 42214 | K32: 91 | L32: 14 | M32: 21 | N32: 125 | O32: 3 | Q32: H2c:38.22 | R32: H2a:37.90 | S32: H2:37.79 | T32: 7.3 | U32: 5.6 | V32: 2.5 | W32: 2.2 | X32: 2.82 | Y32: 3.18 | Z32: 1 | AA32: 144 | AE32: Dwarf Shrub Heath | AF32: Lowland Heathland
A33: B26 | B33: VC | C33: 2015 | D33: 51 | E33: NNR Site Boundary (Heathland) | F33: 490579.99 | G33: 141561.7 | H33: SU9057941561 | J33: 42213 | K33: 61 | L33: 14 | M33: 0 | O33: 2 | Q33: M16a:43.06 | R33: M16:42.55 | S33: M16c:35.62 | T33: 7.6 | U33: 7.3 | V33: 2.2 | W33: 1.4 | X33: 2.42 | Y33: 3.58 | Z33: 1 | AE33: Dwarf Shrub Heath | AF33: Lowland Heathland | AG33: Aspect not recorded. BAP_PRIORITY not recorded. | AH33: DI900
A34: B26 | B34: VC | C34: 2015 | D34: 52 | E34: NNR Site Boundary (Heathland) | F34: 490556.85 | G34: 140377.44 | H34: SU9055640377 | J34: 42213 | K34: 0 | L34: 14 | M34: 12 | N34: 50 | O34: 2 | Q34: H2c:45.74 | R34: H2:42.22 | S34: H3a:41.44 | T34: 7 | U34: 5.7 | V34: 2.4 | W34: 2.3 | X34: 2.66 | Y34: 3.34 | Z34: 1 | AA34: 144 | AE34: Dwarf Shrub Heath | AF34: Lowland Heathland
A35: B26 | B35: VC | C35: 2015 | D35: 53 | E35: NNR Site Boundary (Heathland) | F35: 490428.5 | G35: 140606.06 | H35: SU9042840606 | J35: 42213 | K35: 73 | L35: 14 | M35: 0 | N35: n/a | O35: 2 | Q35: H2:49.92 | R35: H2b:48.30 | S35: H2a:47.78 | T35: 6.4 | U35: 5.1 | V35: 2 | W35: 2.6 | X35: 2.04 | Y35: 3.96 | Z35: 1 | AA35: 144 | AD35: some rabbit droppings. some signs of browsing | AE35: Dwarf Shrub Heath | AF35: Lowland Heathland
A36: B26 | B36: VC | C36: 2015 | D36: 56 | I36: PLOT NOT SURVEYED THIS YEAR | AG36: PLOT NOT SURVEYED THIS YEAR.
A37: B26 | B37: VC | C37: 2015 | D37: 57 | E37: NNR Site Boundary (Heathland) | F37: 490179.22 | G37: 141331.49 | H37: SU9017941331 | J37: 42213 | K37: 58 | L37: 18 | M37: 0 | O37: 2 | Q37: M21b:60.56 | R37: M21:55.64 | S37: M15a:50.72 | T37: 7.5 | U37: 8.1 | V37: 2.7 | W37: 1.6 | X37: 2.43 | Y37: 3.57 | Z37: 1.01 | AA37: 144 | AE37: Fen, Marsh and Swamp | AF37: Lowland Fens | AG37: Aspect not recorded. | AH37: DI900
A38: B26 | B38: VC | C38: 2015 | D38: 58 | E38: NNR Site Boundary (Heathland) | F38: 491038.73 | G38: 140500.86 | H38: SU9103840500 | J38: 42213 | K38: 80 | L38: 14 | M38: 3 | N38: 60 | O38: 3 | Q38: H2a:41.99 | R38: H2:39.22 | S38: H3b:36.70 | T38: 7.1 | U38: 5.5 | V38: 2.5 | W38: 2.3 | X38: 2.65 | Y38: 3.35 | Z38: 1 | AA38: 144 | AE38: Dwarf Shrub Heath | AF38: Lowland Heathland
A39: B26 | B39: VC | C39: 2015 | D39: 59 | E39: NNR Site Boundary (Heathland) | F39: 490829.03 | G39: 140860.99 | H39: SU9082940860 | J39: 42213 | K39: 73 | L39: 14 | M39: 4 | N39: 6 | O39: 1 | Q39: H2a:49.69 | R39: H2:46.03 | S39: H3b:40.40 | T39: 7.2 | U39: 5.9 | V39: 1.9 | W39: 2 | X39: 2.89 | Y39: 3.08 | Z39: 1.03 | AA39: 144 | AD39: rabbit droppings | AE39: Dwarf Shrub Heath | AF39: Lowland Heathland
A40: B26 | B40: VW | C40: 2015 | D40: 60 | E40: NNR Site Boundary (Heathland) | F40: 489874.08 | G40: 141096.46 | H40: SU8987441096 | J40: 42215 | K40: 0 | L40: 14 | Q40: H2a:45.98 | R40: H2:44.21 | S40: H2c:43.28 | T40: 7.1 | U40: 5.9 | V40: 2 | W40: 2 | X40: 2.95 | Y40: 3.05 | Z40: 1 | AA40: 144 | AB40: 147 | AE40: Dwarf Shrub Heath | AF40: Lowland Heathland | AG40: Slope, aspect & slopeform not recorded. Query target habitat. Altitude incorrect. BAP_BROAD not recorded. | AH40: DI900 | AI40: DI990
...

Sheet Species Template
A1: SITECODE | B1: MCODE | C1: YEAR | D1: PLOT_ID | E1: SPECIES_NO | F1: DESC_LATIN | G1: CELL_1 | H1: CELL_2 | I1: CELL_3 | J1: CELL_4 | K1: CELL_5 | L1: CELL_6 | M1: CELL_7 | N1: CELL_8 | O1: CELL_9 | P1: CELL_10 | Q1: CELL_11 | R1: CELL_12 | S1: CELL_13 | T1: CELL_14 | U1: CELL_15 | V1: CELL_16 | W1: CELL_17 | X1: CELL_18 | Y1: CELL_19 | Z1: CELL_20 | AA1: CELL_21 | AB1: CELL_22 | AC1: CELL_23 | AD1: CELL_24 | AE1: CELL_25 | AF1: PERCENT_COVER | AG1: FREQUENCY | AH1: DATA _ENTRY_COMMENTS | AI1: DATA_ISSUE1 | AJ1: DATA_ISSUE2 | AK1: DATA_ISSUE3 | AL1: QA_CODE1 | AM1: QA_CODE2 | AN1: QA_CODE3 | AO1: FINAL_QA
A2: B26 | B2: VC | C2: 2015 | D2: 2 | E2: 278 | F2: Calluna vulgaris | G2: 0 | H2: 1 | I2: 1 | J2: 0 | K2: 0 | L2: 0 | M2: 0 | N2: 0 | O2: 0 | P2: 0 | Q2: 1 | R2: 0 | S2: 0 | T2: 0 | U2: 0 | V2: 0 | W2: 1 | X2: 1 | Y2: 0 | Z2: 0 | AA2: 1 | AB2: 1 | AC2: 1 | AD2: 0 | AE2: 0 | AF2: 15 | AG2: 8
A3: B26 | B3: VC | C3: 2015 | D3: 2 | E3: 1576 | F3: Campylopus introflexus | G3: 1 | H3: 1 | I3: 1 | J3: 1 | K3: 1 | L3: 1 | M3: 1 | N3: 1 | O3: 1 | P3: 1 | Q3: 1 | R3: 1 | S3: 1 | T3: 1 | U3: 1 | V3: 1 | W3: 1 | X3: 1 | Y3: 1 | Z3: 1 | AA3: 1 | AB3: 0 | AC3: 1 | AD3: 1 | AE3: 1 | AF3: 70 | AG3: 24 | AI3: DI806 | AL3: QA606 | AO3: QA606
A4: B26 | B4: VC | C4: 2015 | D4: 2 | E4: 2694 | F4: Cladonia | G4: 1 | H4: 1 | I4: 1 | J4: 1 | K4: 1 | L4: 0 | M4: 1 | N4: 1 | O4: 1 | P4: 1 | Q4: 1 | R4: 1 | S4: 1 | T4: 1 | U4: 1 | V4: 1 | W4: 1 | X4: 1 | Y4: 1 | Z4: 1 | AA4: 1 | AB4: 0 | AC4: 1 | AD4: 1 | AE4: 1 | AF4: 2 | AG4: 23 | AH4: no sample. Idenitified to genus only. | AI4: DI808 | AM4: QA607 | AO4: QA607
A5: B26 | B5: VC | C5: 2015 | D5: 2 | E5: 2388 | F5: Cladonia subulata | G5: 0 | H5: 0 | I5: 1 | J5: 1 | K5: 0 | L5: 0 | M5: 0 | N5: 0 | O5: 0 | P5: 0 | Q5: 0 | R5: 0 | S5: 0 | T5: 0 | U5: 0 | V5: 0 | W5: 0 | X5: 0 | Y5: 0 | Z5: 0 | AA5: 0 | AB5: 0 | AC5: 0 | AD5: 0 | AE5: 0 | AF5: 0.1 | AG5: 2 | AI5: DI805 | AL5: QA600 | AM5: QA605 | AO5: QA605
A6: B26 | B6: VC | C6: 2015 | D6: 2 | E6: 541 | F6: Erica cinerea | G6: 1 | H6: 1 | I6: 1 | J6: 1 | K6: 1 | L6: 1 | M6: 1 | N6: 1 | O6: 1 | P6: 1 | Q6: 1 | R6: 1 | S6: 1 | T6: 0 | U6: 0 | V6: 1 | W6: 1 | X6: 1 | Y6: 1 | Z6: 0 | AA6: 1 | AB6: 1 | AC6: 1 | AD6: 1 | AE6: 1 | AF6: 30 | AG6: 22
A7: B26 | B7: VC | C7: 2015 | D7: 2 | E7: 2416 | F7: Hypogymnia physodes | G7: 0 | H7: 1 | I7: 0 | J7: 1 | K7: 1 | L7: 1 | M7: 1 | N7: 1 | O7: 1 | P7: 1 | Q7: 0 | R7: 0 | S7: 0 | T7: 0 | U7: 0 | V7: 0 | W7: 1 | X7: 1 | Y7: 0 | Z7: 0 | AA7: 1 | AB7: 1 | AC7: 1 | AD7: 1 | AE7: 1 | AF7: 0.1 | AG7: 15 | AI7: DI805 | AL7: QA600 | AM7: QA605 | AO7: QA605
A8: B26 | B8: VC | C8: 2015 | D8: 2 | E8: 971 | F8: Pinus sylvestris (c) | G8: 0 | H8: 1 | I8: 1 | J8: 1 | K8: 1 | L8: 0 | M8: 0 | N8: 0 | O8: 1 | P8: 0 | Q8: 1 | R8: 1 | S8: 0 | T8: 0 | U8: 0 | V8: 1 | W8: 1 | X8: 1 | Y8: 1 | Z8: 0 | AA8: 1 | AB8: 1 | AC8: 0 | AD8: 1 | AE8: 0 | AF8: 1 | AG8: 14
A9: B26 | B9: VC | C9: 2015 | D9: 2 | E9: 1894 | F9: Polytrichum juniperinum | G9: 1 | H9: 1 | I9: 1 | J9: 1 | K9: 1 | L9: 1 | M9: 1 | N9: 1 | O9: 1 | P9: 1 | Q9: 1 | R9: 1 | S9: 1 | T9: 1 | U9: 1 | V9: 1 | W9: 1 | X9: 1 | Y9: 1 | Z9: 1 | AA9: 1 | AB9: 0 | AC9: 1 | AD9: 1 | AE9: 1 | AF9: 2 | AG9: 24
A10: B26 | B10: VC | C10: 2015 | D10: 2 | E10: 1066 | F10: Pteridium aquilinum | G10: 0 | H10: 0 | I10: 0 | J10: 0 | K10: 1 | L10: 0 | M10: 0 | N10: 0 | O10: 1 | P10: 1 | Q10: 1 | R10: 0 | S10: 0 | T10: 1 | U10: 1 | V10: 0 | W10: 0 | X10: 0 | Y10: 1 | Z10: 0 | AA10: 0 | AB10: 1 | AC10: 0 | AD10: 0 | AE10: 0 | AF10: 8 | AG10: 8
A11: B26 | B11: VC | C11: 2015 | D11: 3 | E11: 2607 | F11: Betula pendula (g) | G11: 1 | H11: 0 | I11: 0 | J11: 0 | K11: 0 | L11: 0 | M11: 0 | N11: 0 | O11: 0 | P11: 0 | Q11: 0 | R11: 0 | S11: 0 | T11: 0 | U11: 0 | V11: 0 | W11: 0 | X11: 0 | Y11: 0 | Z11: 0 | AA11: 0 | AB11: 0 | AC11: 0 | AD11: 0 | AE11: 0 | AF11: 0.1 | AG11: 1 | AI11: DI805 | AL11: QA600 | AO11: QA600
A12: B26 | B12: VC | C12: 2015 | D12: 3 | E12: 278 | F12: Calluna vulgaris | G12: 0 | H12: 0 | I12: 0 | J12: 0 | K12: 1 | L12: 0 | M12: 0 | N12: 0 | O12: 0 | P12: 0 | Q12: 0 | R12: 1 | S12: 0 | T12: 0 | U12: 0 | V12: 0 | W12: 0 | X12: 0 | Y12: 0 | Z12: 0 | AA12: 0 | AB12: 0 | AC12: 0 | AD12: 0 | AE12: 0 | AF12: 1 | AG12: 2
A13: B26 | B13: VC | C13: 2015 | D13: 3 | E13: 1576 | F13: Campylopus introflexus | G13: 0 | H13: 1 | I13: 1 | J13: 1 | K13: 0 | L13: 0 | M13: 1 | N13: 1 | O13: 0 | P13: 0 | Q13: 0 | R13: 1 | S13: 1 | T13: 0 | U13: 1 | V13: 0 | W13: 1 | X13: 1 | Y13: 1 | Z13: 0 | AA13: 0 | AB13: 0 | AC13: 1 | AD13: 1 | AE13: 1 | AF13: 8 | AG13: 14
A14: B26 | B14: VC | C14: 2015 | D14: 3 | E14: 2359 | F14: Cladonia fimbriata | G14: 0 | H14: 1 | I14: 1 | J14: 1 | K14: 1 | L14: 0 | M14: 0 | N14: 0 | O14: 0 | P14: 0 | Q14: 0 | R14: 0 | S14: 1 | T14: 0 | U14: 0 | V14: 0 | W14: 0 | X14: 1 | Y14: 0 | Z14: 0 | AA14: 0 | AB14: 0 | AC14: 1 | AD14: 0 | AE14: 0 | AF14: 0.1 | AG14: 7 | AI14: DI805 | AL14: QA600 | AO14: QA600
A15: B26 | B15: VC | C15: 2015 | D15: 3 | E15: 2362 | F15: Cladonia furcata | G15: 0 | H15: 0 | I15: 0 | J15: 0 | K15: 0 | L15: 0 | M15: 0 | N15: 0 | O15: 0 | P15: 1 | Q15: 0 | R15: 0 | S15: 0 | T15: 0 | U15: 0 | V15: 0 | W15: 0 | X15: 0 | Y15: 0 | Z15: 0 | AA15: 0 | AB15: 0 | AC15: 1 | AD15: 0 | AE15: 0 | AF15: 0.1 | AG15: 2 | AI15: DI805 | AL15: QA600 | AO15: QA600
A16: B26 | B16: VC | C16: 2015 | D16: 3 | E16: 478 | F16: Deschampsia flexuosa | G16: 1 | H16: 1 | I16: 1 | J16: 1 | K16: 1 | L16: 1 | M16: 1 | N16: 1 | O16: 1 | P16: 1 | Q16: 1 | R16: 1 | S16: 1 | T16: 1 | U16: 1 | V16: 1 | W16: 1 | X16: 1 | Y16: 1 | Z16: 1 | AA16: 1 | AB16: 0 | AC16: 1 | AD16: 1 | AE16: 1 | AF16: 20 | AG16: 24 | AH16: recorded twice - other line deleted | AI16: DI809
A17: B26 | B17: VC | C17: 2015 | D17: 3 | E17: 1638 | F17: Dicranum scoparium | G17: 1 | H17: 0 | I17: 1 | J17: 1 | K17: 0 | L17: 1 | M17: 0 | N17: 0 | O17: 1 | P17: 0 | Q17: 1 | R17: 1 | S17: 1 | T17: 1 | U17: 0 | V17: 1 | W17: 0 | X17: 1 | Y17: 0 | Z17: 0 | AA17: 0 | AB17: 0 | AC17: 1 | AD17: 1 | AE17: 0 | AF17: 2 | AG17: 13
A18: B26 | B18: VC | C18: 2015 | D18: 3 | E18: 541 | F18: Erica cinerea | G18: 1 | H18: 1 | I18: 1 | J18: 1 | K18: 1 | L18: 0 | M18: 1 | N18: 1 | O18: 1 | P18: 1 | Q18: 1 | R18: 1 | S18: 1 | T18: 1 | U18: 1 | V18: 1 | W18: 1 | X18: 1 | Y18: 1 | Z18: 1 | AA18: 1 | AB18: 1 | AC18: 0 | AD18: 1 | AE18: 1 | AF18: 25 | AG18: 23
A19: B26 | B19: VC | C19: 2015 | D19: 3 | E19: 2695 | F19: Hypnum jutlandicum | G19: 1 | H19: 0 | I19: 1 | J19: 1 | K19: 1 | L19: 0 | M19: 1 | N19: 1 | O19: 0 | P19: 0 | Q19: 1 | R19: 1 | S19: 1 | T19: 1 | U19: 1 | V19: 0 | W19: 1 | X19: 1 | Y19: 1 | Z19: 1 | AA19: 0 | AB19: 0 | AC19: 1 | AD19: 0 | AE19: 0 | AF19: 5 | AG19: 16
A20: B26 | B20: VC | C20: 2015 | D20: 3 | E20: 2620 | F20: Pinus sylvestris (g) | G20: 1 | H20: 1 | I20: 1 | J20: 0 | K20: 1 | L20: 1 | M20: 1 | N20: 1 | O20: 1 | P20: 0 | Q20: 1 | R20: 0 | S20: 0 | T20: 0 | U20: 0 | V20: 0 | W20: 0 | X20: 0 | Y20: 0 | Z20: 0 | AA20: 0 | AB20: 0 | AC20: 0 | AD20: 1 | AE20: 0 | AF20: 0.1 | AG20: 10 | AI20: DI805 | AL20: QA600 | AO20: QA600
A21: B26 | B21: VC | C21: 2015 | D21: 3 | E21: 1894 | F21: Polytrichum juniperinum | G21: 0 | H21: 1 | I21: 1 | J21: 1 | K21: 1 | L21: 0 | M21: 1 | N21: 1 | O21: 0 | P21: 0 | Q21: 0 | R21: 0 | S21: 0 | T21: 0 | U21: 0 | V21: 1 | W21: 0 | X21: 0 | Y21: 1 | Z21: 0 | AA21: 0 | AB21: 0 | AC21: 1 | AD21: 1 | AE21: 0 | AF21: 0.1 | AG21: 10 | AI21: DI805 | AL21: QA600 | AO21: QA600
A22: B26 | B22: VC | C22: 2015 | D22: 3 | E22: 1046 | F22: Potentilla erecta | G22: 0 | H22: 0 | I22: 0 | J22: 0 | K22: 0 | L22: 0 | M22: 0 | N22: 0 | O22: 0 | P22: 0 | Q22: 0 | R22: 0 | S22: 0 | T22: 0 | U22: 0 | V22: 0 | W22: 0 | X22: 0 | Y22: 0 | Z22: 0 | AA22: 0 | AB22: 0 | AC22: 0 | AD22: 0 | AE22: 1 | AF22: 0.1 | AG22: 1
A23: B26 | B23: VC | C23: 2015 | D23: 3 | E23: 1914 | F23: Pseudoscleropodium purum | G23: 1 | H23: 1 | I23: 0 | J23: 0 | K23: 0 | L23: 1 | M23: 0 | N23: 0 | O23: 0 | P23: 0 | Q23: 1 | R23: 0 | S23: 0 | T23: 0 | U23: 1 | V23: 1 | W23: 1 | X23: 0 | Y23: 0 | Z23: 0 | AA23: 1 | AB23: 1 | AC23: 1 | AD23: 1 | AE23: 0 | AF23: 3 | AG23: 11
A24: B26 | B24: VC | C24: 2015 | D24: 6 | E24: 278 | F24: Calluna vulgaris | G24: 1 | H24: 1 | I24: 1 | J24: 1 | K24: 0 | L24: 1 | M24: 1 | N24: 1 | O24: 1 | P24: 0 | Q24: 0 | R24: 0 | S24: 0 | T24: 0 | U24: 0 | V24: 1 | W24: 0 | X24: 0 | Y24: 1 | Z24: 1 | AA24: 1 | AB24: 1 | AC24: 0 | AD24: 0 | AE24: 0 | AF24: 1 | AG24: 13
A25: B26 | B25: VC | C25: 2015 | D25: 6 | E25: 3192 | F25: Dactylorhiza | G25: 0 | H25: 0 | I25: 0 | J25: 0 | K25: 0 | L25: 0 | M25: 0 | N25: 0 | O25: 0 | P25: 0 | Q25: 0 | R25: 0 | S25: 0 | T25: 0 | U25: 0 | V25: 0 | W25: 0 | X25: 0 | Y25: 0 | Z25: 0 | AA25: 0 | AB25: 0 | AC25: 0 | AD25: 1 | AE25: 0 | AF25: 0.1 | AG25: 1 | AH25: Idenitified to genus only. No sample. Orchid sp. (Marsh?) | AI25: DI805 | AJ25: DI807 | AL25: QA600 | AM25: QA607 | AO25: QA607
A26: B26 | B26: VC | C26: 2015 | D26: 6 | E26: 494 | F26: Drosera rotundifolia | G26: 1 | H26: 1 | I26: 1 | J26: 1 | K26: 1 | L26: 1 | M26: 1 | N26: 1 | O26: 1 | P26: 1 | Q26: 0 | R26: 1 | S26: 1 | T26: 1 | U26: 1 | V26: 0 | W26: 1 | X26: 1 | Y26: 1 | Z26: 1 | AA26: 1 | AB26: 1 | AC26: 0 | AD26: 1 | AE26: 1 | AF26: 3 | AG26: 22
A27: B26 | B27: VC | C27: 2015 | D27: 6 | E27: 542 | F27: Erica tetralix | G27: 1 | H27: 1 | I27: 1 | J27: 1 | K27: 1 | L27: 1 | M27: 1 | N27: 1 | O27: 1 | P27: 1 | Q27: 1 | R27: 1 | S27: 1 | T27: 1 | U27: 1 | V27: 1 | W27: 1 | X27: 1 | Y27: 1 | Z27: 1 | AA27: 1 | AB27: 1 | AC27: 1 | AD27: 1 | AE27: 1 | AF27: 15 | AG27: 25
A28: B26 | B28: VC | C28: 2015 | D28: 6 | E28: 546 | F28: Eriophorum angustifolium | G28: 1 | H28: 1 | I28: 1 | J28: 1 | K28: 1 | L28: 1 | M28: 0 | N28: 1 | O28: 1 | P28: 1 | Q28: 1 | R28: 1 | S28: 1 | T28: 1 | U28: 1 | V28: 1 | W28: 1 | X28: 0 | Y28: 1 | Z28: 1 | AA28: 1 | AB28: 1 | AC28: 1 | AD28: 1 | AE28: 1 | AF28: 3 | AG28: 23
A29: B26 | B29: VC | C29: 2015 | D29: 6 | E29: 876 | F29: Molinia caerulea | G29: 1 | H29: 1 | I29: 1 | J29: 1 | K29: 1 | L29: 1 | M29: 1 | N29: 1 | O29: 1 | P29: 1 | Q29: 1 | R29: 1 | S29: 1 | T29: 1 | U29: 1 | V29: 1 | W29: 1 | X29: 1 | Y29: 1 | Z29: 1 | AA29: 1 | AB29: 1 | AC29: 1 | AD29: 1 | AE29: 1 | AF29: 15 | AG29: 25
A30: B26 | B30: VC | C30: 2015 | D30: 6 | E30: 901 | F30: Narthecium ossifragum | G30: 0 | H30: 0 | I30: 0 | J30: 1 | K30: 0 | L30: 1 | M30: 1 | N30: 1 | O30: 0 | P30: 0 | Q30: 0 | R30: 0 | S30: 1 | T30: 0 | U30: 1 | V30: 1 | W30: 0 | X30: 1 | Y30: 1 | Z30: 1 | AA30: 1 | AB30: 1 | AE30: 1 | AF30: 0.1 | AG30: 13 | AI30: DI805 | AL30: QA600 | AO30: QA600
A31: B26 | B31: VC | C31: 2015 | D31: 6 | E31: 4292 | F31: Pinus seedling | G31: 1 | H31: 0 | I31: 0 | J31: 0 | K31: 0 | L31: 0 | M31: 0 | N31: 0 | O31: 0 | P31: 0 | Q31: 0 | R31: 0 | S31: 0 | T31: 0 | U31: 0 | V31: 0 | W31: 0 | X31: 0 | Y31: 0 | Z31: 0 | AA31: 0 | AB31: 0 | AC31: 0 | AD31: 0 | AE31: 0 | AF31: 5 | AG31: 1 | AH31: Pine stage not recorded on field form | AI31: DI814
A32: B26 | B32: VC | C32: 2015 | D32: 6 | E32: 1109 | F32: Rhynchospora alba | G32: 0 | H32: 0 | I32: 0 | J32: 1 | K32: 1 | L32: 1 | M32: 1 | N32: 1 | O32: 1 | P32: 1 | Q32: 1 | R32: 1 | S32: 1 | T32: 0 | U32: 1 | V32: 1 | W32: 1 | X32: 1 | Y32: 1 | Z32: 1 | AA32: 1 | AB32: 1 | AC32: 1 | AD32: 0 | AE32: 1 | AF32: 10 | AG32: 20
A33: B26 | B33: VC | C33: 2015 | D33: 6 | E33: 6026 | F33: Sphagnum denticulatum s.l. | G33: 1 | H33: 0 | I33: 0 | J33: 1 | K33: 1 | L33: 0 | M33: 0 | N33: 0 | O33: 0 | P33: 1 | Q33: 1 | R33: 1 | S33: 1 | T33: 0 | U33: 1 | V33: 0 | W33: 0 | X33: 1 | Y33: 0 | Z33: 0 | AA33: 0 | AB33: 1 | AC33: 1 | AD33: 1 | AE33: 1 | AF33: 15 | AG33: 13 | AL33: QA606 | AO33: QA606
A34: B26 | B34: VC | C34: 2015 | D34: 6 | E34: 1971 | F34: Sphagnum palustre | G34: 0 | H34: 0 | I34: 0 | J34: 0 | K34: 0 | L34: 0 | M34: 0 | N34: 0 | O34: 0 | P34: 0 | Q34: 0 | R34: 1 | S34: 0 | T34: 0 | U34: 0 | V34: 0 | W34: 0 | X34: 0 | Y34: 0 | Z34: 0 | AA34: 0 | AB34: 1 | AC34: 0 | AD34: 0 | AE34: 0 | AF34: 2 | AG34: 2
A35: B26 | B35: VC | C35: 2015 | D35: 6 | E35: 1972 | F35: Sphagnum papillosum | G35: 1 | H35: 1 | I35: 1 | J35: 1 | K35: 1 | L35: 1 | M35: 1 | N35: 1 | O35: 1 | P35: 1 | Q35: 1 | R35: 1 | S35: 1 | T35: 1 | U35: 1 | V35: 1 | W35: 1 | X35: 1 | Y35: 1 | Z35: 1 | AA35: 1 | AB35: 1 | AC35: 0 | AD35: 0 | AE35: 1 | AF35: 40 | AG35: 23 | AH35: 2 species recorded by expert in sample bag - unclear which species the cell data belong to. Sphag papillosum recorded next to sample name though so assigned to this & S. tenellum added as separate line. | AI35: DI810 | AL35: QA605 | AM35: QA602 | AO35: QA602
A36: B26 | B36: VC | C36: 2015 | D36: 6 | E36: 1984 | F36: Sphagnum tenellum | G36: 1 | H36: 0 | I36: 0 | J36: 0 | K36: 0 | L36: 0 | M36: 0 | N36: 0 | O36: 0 | P36: 0 | Q36: 0 | R36: 0 | S36: 0 | T36: 0 | U36: 0 | V36: 0 | W36: 0 | X36: 0 | Y36: 0 | Z36: 0 | AA36: 0 | AB36: 0 | AC36: 0 | AD36: 0 | AE36: 0 | AG36: 1 | AH36: ID confirmed by specialist for moss D but entered as separate line. No PERCENT_COVER recorded. | AI36: DI810 | AJ36: DI802 | AK36: DI800 | AL36: QA601 | AM36: QA608 | AN36: QA777 | AO36: QA777
A37: B26 | B37: VC | C37: 2015 | D37: 7 | E37: 278 | F37: Calluna vulgaris | G37: 1 | H37: 1 | I37: 1 | J37: 1 | K37: 1 | L37: 0 | M37: 0 | N37: 1 | O37: 1 | P37: 0 | Q37: 0 | R37: 0 | S37: 1 | T37: 1 | U37: 0 | V37: 1 | W37: 1 | X37: 1 | Y37: 0 | Z37: 1 | AA37: 0 | AB37: 1 | AC37: 1 | AD37: 0 | AE37: 1 | AF37: 20 | AG37: 16
A38: B26 | B38: VC | C38: 2015 | D38: 7 | E38: 1576 | F38: Campylopus introflexus | G38: 0 | H38: 0 | I38: 0 | J38: 0 | K38: 0 | L38: 1 | M38: 0 | N38: 0 | O38: 0 | P38: 0 | Q38: 1 | R38: 0 | S38: 0 | T38: 0 | U38: 0 | V38: 0 | W38: 0 | X38: 0 | Y38: 0 | Z38: 1 | AA38: 1 | AB38: 0 | AC38: 0 | AD38: 0 | AE38: 0 | AF38: 0.1 | AG38: 4 | AH38: merged with Moss A | AI38: DI805 | AJ38: DI809 | AL38: QA600 | AM38: QA605 | AN38: QA777 | AO38: QA777
A39: B26 | B39: VC | C39: 2015 | D39: 7 | E39: 2694 | F39: Cladonia | G39: 0 | H39: 0 | I39: 0 | J39: 0 | K39: 0 | L39: 0 | M39: 0 | N39: 0 | O39: 0 | P39: 1 | Q39: 0 | R39: 0 | S39: 0 | T39: 0 | U39: 0 | V39: 0 | W39: 0 | X39: 0 | Y39: 0 | Z39: 0 | AA39: 0 | AB39: 0 | AC39: 0 | AD39: 0 | AE39: 0 | AF39: 0.1 | AG39: 1 | AH39: moss & lichen id but no liverwort in bag - dubious record - assigned as Cladonia as P. junip already recorded. | AI39: DI810 | AJ39: DI805 | AK39: DI809 | AL39: QA603 | AM39: QA605 | AN39: QA788 | AO39: QA788
A40: B26 | B40: VC | C40: 2015 | D40: 7 | E40: 6003 | F40: Cladonia diversa | G40: 1 | H40: 1 | I40: 1 | J40: 0 | K40: 1 | L40: 0 | M40: 1 | N40: 1 | O40: 0 | P40: 1 | Q40: 1 | R40: 1 | S40: 1 | T40: 0 | U40: 1 | V40: 1 | W40: 0 | X40: 1 | Y40: 1 | Z40: 1 | AA40: 1 | AB40: 0 | AC40: 0 | AD40: 0 | AE40: 0 | AF40: 0.1 | AG40: 16 | AI40: DI805 | AL40: QA600 | AO40: QA600
...

Sheet Ground Features
A1: SITECODE | B1: MCODE | C1: YEAR | D1: PLOT_ID | E1: FEATURE | F1: CELL_1 | G1: CELL_2 | H1: CELL_3 | I1: CELL_4 | J1: CELL_5 | K1: CELL_6 | L1: CELL_7 | M1: CELL_8 | N1: CELL_9 | O1: CELL_10 | P1: CELL_11 | Q1: CELL_12 | R1: CELL_13 | S1: CELL_14 | T1: CELL_15 | U1: CELL_16 | V1: CELL_17 | W1: CELL_18 | X1: CELL_19 | Y1: CELL_20 | Z1: CELL_21 | AA1: CELL_22 | AB1: CELL_23 | AC1: CELL_24 | AD1: CELL_25 | AE1: PERCENT_COVER | AF1: FREQUENCY | AG1: DATA_ENTRY_COMMENTS | AH1: DATA_ISSUE1 | AI1: DATA_ISSUE2 | AJ1: DATA_ISSUE3 | AK1: QA_CODE1 | AL1: QA_CODE2 | AM1: QA_CODE3 | AN1: FINAL_QA
A2: B26 | B2: VC | C2: 2015 | D2: 2 | E2: Vegetation height | F2: 8 | G2: 33.5 | H2: 17 | I2: 20 | J2: 30 | K2: 2.5 | L2: 22 | M2: 12.5 | N2: 12.5 | O2: 7.5 | P2: 7.5 | Q2: 2 | R2: 2 | S2: 1.5 | T2: 4 | U2: 5 | V2: 9 | W2: 15.5 | X2: 7 | Y2: 1.5 | Z2: 10.5 | AA2: 38 | AB2: 7.5 | AC2: 6 | AD2: 12
A3: B26 | B3: VC | C3: 2015 | D3: 2 | E3: Litter | F3: 1 | G3: 1 | H3: 1 | I3: 1 | J3: 1 | K3: 1 | L3: 1 | M3: 1 | N3: 1 | O3: 1 | P3: 1 | Q3: 1 | R3: 1 | S3: 1 | T3: 1 | U3: 1 | V3: 1 | W3: 1 | X3: 1 | Y3: 1 | Z3: 1 | AA3: 1 | AB3: 1 | AC3: 1 | AD3: 1 | AE3: 60 | AF3: 25
A4: B26 | B4: VC | C4: 2015 | D4: 2 | E4: Bare soil | F4: 0 | G4: 0 | H4: 0 | I4: 0 | J4: 0 | K4: 0 | L4: 0 | M4: 0 | N4: 0 | O4: 0 | P4: 0 | Q4: 0 | R4: 0 | S4: 1 | T4: 1 | U4: 0 | V4: 0 | W4: 0 | X4: 0 | Y4: 0 | Z4: 0 | AA4: 0 | AB4: 0 | AC4: 0 | AD4: 0 | AE4: 0.1 | AF4: 2 | AH4: DI805 | AK4: QA600 | AN4: QA600
A5: B26 | B5: VC | C5: 2015 | D5: 3 | E5: Vegetation height | F5: 6 | G5: 2.5 | H5: 1.5 | I5: 3 | J5: 6 | K5: 8 | L5: 3 | M5: 5 | N5: 17 | O5: 20 | P5: 7 | Q5: 4 | R5: 2 | S5: 9 | T5: 11.5 | U5: 4 | V5: 4.5 | W5: 3 | X5: 10 | Y5: 14 | Z5: 10 | AA5: 6 | AB5: 1.5 | AC5: 3 | AD5: 8
A6: B26 | B6: VC | C6: 2015 | D6: 3 | E6: Bare soil | F6: 0 | G6: 1 | H6: 1 | I6: 0 | J6: 0 | K6: 0 | L6: 1 | M6: 0 | N6: 0 | O6: 0 | P6: 0 | Q6: 0 | R6: 0 | S6: 0 | T6: 0 | U6: 0 | V6: 0 | W6: 0 | X6: 0 | Y6: 0 | Z6: 0 | AA6: 0 | AB6: 0 | AC6: 0 | AD6: 0 | AE6: 0.1 | AF6: 3 | AH6: DI805 | AK6: QA600 | AN6: QA600
A7: B26 | B7: VC | C7: 2015 | D7: 3 | E7: Litter | F7: 1 | G7: 1 | H7: 1 | I7: 1 | J7: 1 | K7: 1 | L7: 1 | M7: 1 | N7: 1 | O7: 1 | P7: 1 | Q7: 1 | R7: 1 | S7: 1 | T7: 1 | U7: 1 | V7: 1 | W7: 1 | X7: 1 | Y7: 1 | Z7: 1 | AA7: 1 | AB7: 1 | AC7: 1 | AD7: 1 | AE7: 4 | AF7: 25
A8: B26 | B8: VC | C8: 2015 | D8: 6 | E8: Vegetation height | F8: 6 | G8: 10.5 | H8: 13 | I8: 5.5 | J8: 6.5 | K8: 10 | L8: 10 | M8: 8.5 | N8: 7.5 | O8: 10.5 | P8: 12.5 | Q8: 8.5 | R8: 6.5 | S8: 11.5 | T8: 8 | U8: 12.5 | V8: 9.5 | W8: 10.5 | X8: 13 | Y8: 7 | Z8: 10.5 | AA8: 10.5 | AB8: 11.5 | AC8: 13.5 | AD8: 10.5
A9: B26 | B9: VC | C9: 2015 | D9: 6 | E9: Litter | F9: 1 | G9: 1 | H9: 1 | I9: 1 | J9: 1 | K9: 1 | L9: 1 | M9: 1 | N9: 1 | O9: 1 | P9: 1 | Q9: 1 | R9: 1 | S9: 1 | T9: 1 | U9: 1 | V9: 1 | W9: 1 | X9: 1 | Y9: 1 | Z9: 1 | AA9: 1 | AB9: 1 | AC9: 1 | AD9: 1 | AE9: 10 | AF9: 25
A10: B26 | B10: VC | C10: 2015 | D10: 6 | E10: Bare peat | F10: 0 | G10: 0 | H10: 0 | I10: 0 | J10: 0 | K10: 0 | L10: 0 | M10: 0 | N10: 0 | O10: 0 | P10: 0 | Q10: 0 | R10: 0 | S10: 0 | T10: 1 | U10: 0 | V10: 0 | W10: 0 | X10: 0 | Y10: 0 | Z10: 0 | AA10: 0 | AB10: 0 | AC10: 0 | AD10: 0 | AE10: 0.1 | AF10: 1
A11: B26 | B11: VC | C11: 2015 | D11: 7 | E11: Vegetation height | F11: 14 | G11: 27 | H11: 35 | I11: 28 | J11: 7 | K11: 10 | L11: 11 | M11: 10 | N11: 28 | O11: 22 | P11: 20 | Q11: 8 | R11: 11 | S11: 39 | T11: 37 | U11: 17 | V11: 33 | W11: 23 | X11: 20 | Y11: 7 | Z11: 10 | AA11: 33 | AB11: 25 | AC11: 15 | AD11: 33
A12: B26 | B12: VC | C12: 2015 | D12: 7 | E12: Bare soil | F12: 1 | G12: 0 | H12: 0 | I12: 0 | J12: 0 | K12: 0 | L12: 0 | M12: 0 | N12: 0 | O12: 0 | P12: 0 | Q12: 1 | R12: 0 | S12: 1 | T12: 0 | U12: 0 | V12: 0 | W12: 0 | X12: 0 | Y12: 0 | Z12: 0 | AA12: 0 | AB12: 0 | AC12: 0 | AD12: 0 | AE12: 0.1 | AF12: 3 | AH12: DI805 | AK12: QA600 | AN12: QA600
A13: B26 | B13: VC | C13: 2015 | D13: 7 | E13: Litter | F13: 1 | G13: 1 | H13: 1 | I13: 1 | J13: 1 | K13: 1 | L13: 1 | M13: 1 | N13: 1 | O13: 1 | P13: 1 | Q13: 1 | R13: 0 | S13: 1 | T13: 1 | U13: 1 | V13: 1 | W13: 1 | X13: 1 | Y13: 1 | Z13: 1 | AA13: 1 | AB13: 0 | AC13: 0 | AD13: 0 | AE13: 75 | AF13: 21
A14: B26 | B14: VC | C14: 2015 | D14: 8 | E14: Vegetation height | F14: 17.5 | G14: 15 | H14: 11.5 | I14: 11 | J14: 7.5 | K14: 23.5 | L14: 15 | M14: 18 | N14: 9 | O14: 9.5 | P14: 20 | Q14: 18 | R14: 26 | S14: 8 | T14: 6 | U14: 9 | V14: 26 | W14: 19 | X14: 9.5 | Y14: 4.5 | Z14: 8.5 | AA14: 11.5 | AB14: 9.5 | AC14: 14 | AD14: 6.5
A15: B26 | B15: VC | C15: 2015 | D15: 8 | E15: Bare soil | F15: 0 | G15: 1 | H15: 0 | I15: 0 | J15: 0 | K15: 0 | L15: 0 | M15: 0 | N15: 0 | O15: 0 | P15: 0 | Q15: 0 | R15: 0 | S15: 0 | T15: 0 | U15: 0 | V15: 0 | W15: 0 | X15: 0 | Y15: 0 | Z15: 0 | AA15: 0 | AB15: 0 | AC15: 0 | AD15: 0 | AF15: 1 | AG15: PERCENT_COVER not recorded. | AH15: DI800
A16: B26 | B16: VC | C16: 2015 | D16: 8 | E16: Litter | F16: 1 | G16: 1 | H16: 1 | I16: 1 | J16: 1 | K16: 1 | L16: 1 | M16: 1 | N16: 1 | O16: 1 | P16: 1 | Q16: 1 | R16: 1 | S16: 1 | T16: 1 | U16: 1 | V16: 1 | W16: 1 | X16: 1 | Y16: 1 | Z16: 1 | AA16: 1 | AB16: 1 | AC16: 1 | AD16: 1 | AE16: 80 | AF16: 25
A17: B26 | B17: VC | C17: 2015 | D17: 11 | E17: Vegetation height | F17: 15 | G17: 12 | H17: 19 | I17: 17 | J17: 27 | K17: 32 | L17: 37 | M17: 21 | N17: 20 | O17: 22 | P17: 13 | Q17: 13 | R17: 21 | S17: 30 | T17: 20 | U17: 21 | V17: 22 | W17: 11 | X17: 67 | Y17: 47 | Z17: 15 | AA17: 8 | AB17: 37 | AC17: 32 | AD17: 43
A18: B26 | B18: VC | C18: 2015 | D18: 11 | E18: Bare soil | F18: 0 | G18: 0 | H18: 1 | I18: 0 | J18: 0 | K18: 0 | L18: 0 | M18: 0 | N18: 0 | O18: 0 | P18: 0 | Q18: 0 | R18: 0 | S18: 0 | T18: 0 | U18: 0 | V18: 0 | W18: 0 | X18: 0 | Y18: 0 | Z18: 0 | AA18: 1 | AB18: 0 | AC18: 0 | AD18: 0 | AE18: 0.1 | AF18: 2 | AH18: DI805 | AK18: QA600 | AN18: QA600
A19: B26 | B19: VC | C19: 2015 | D19: 11 | E19: Litter | F19: 1 | G19: 1 | H19: 1 | I19: 1 | J19: 1 | K19: 1 | L19: 1 | M19: 1 | N19: 1 | O19: 1 | P19: 1 | Q19: 1 | R19: 1 | S19: 1 | T19: 1 | U19: 1 | V19: 1 | W19: 1 | X19: 1 | Y19: 1 | Z19: 1 | AA19: 1 | AB19: 1 | AC19: 1 | AD19: 1 | AE19: 90 | AF19: 25
A20: B26 | B20: VC | C20: 2015 | D20: 12 | E20: Vegetation height | F20: 18.5 | G20: 23.5 | H20: 15 | I20: 4 | J20: 20 | K20: 14.5 | L20: 18 | M20: 20.5 | N20: 15 | O20: 44 | P20: 22.5 | Q20: 19 | R20: 20 | S20: 15 | T20: 23.5 | U20: 15 | V20: 20 | W20: 17 | X20: 15 | Y20: 15.5 | Z20: 18.5 | AA20: 19 | AB20: 33 | AC20: 8.5 | AD20: 21
A21: B26 | B21: VC | C21: 2015 | D21: 12 | E21: Litter | F21: 0 | G21: 1 | H21: 1 | I21: 1 | J21: 1 | K21: 0 | L21: 1 | M21: 1 | N21: 1 | O21: 0 | P21: 0 | Q21: 1 | R21: 1 | S21: 1 | T21: 1 | U21: 1 | V21: 1 | W21: 0 | X21: 1 | Y21: 1 | Z21: 0 | AA21: 1 | AB21: 1 | AC21: 1 | AD21: 1 | AE21: 15 | AF21: 19
A22: B26 | B22: VC | C22: 2015 | D22: 13 | E22: Vegetation height | F22: 2 | G22: 1 | H22: 3.5 | I22: 16.5 | J22: 2.5 | K22: 1.5 | L22: 1 | M22: 2 | N22: 3 | O22: 3 | P22: 2 | Q22: 30 | R22: 1.5 | S22: 13 | T22: 21.5 | U22: 2.5 | V22: 2.5 | W22: 8 | X22: 20 | Y22: 7.5 | Z22: 7.5 | AA22: 11 | AB22: 6.5 | AC22: 24 | AD22: 20.5
A23: B26 | B23: VC | C23: 2015 | D23: 13 | E23: Bare soil | F23: 1 | G23: 1 | H23: 1 | I23: 1 | J23: 0 | K23: 0 | L23: 0 | M23: 0 | N23: 0 | O23: 0 | P23: 0 | Q23: 0 | R23: 0 | S23: 0 | T23: 0 | U23: 0 | V23: 0 | W23: 0 | X23: 0 | Y23: 0 | Z23: 0 | AA23: 0 | AB23: 0 | AC23: 0 | AD23: 0 | AE23: 6 | AF23: 4
A24: B26 | B24: VC | C24: 2015 | D24: 13 | E24: Litter | F24: 1 | G24: 1 | H24: 1 | I24: 1 | J24: 0 | K24: 0 | L24: 0 | M24: 0 | N24: 0 | O24: 0 | P24: 0 | Q24: 0 | R24: 0 | S24: 0 | T24: 0 | U24: 0 | V24: 0 | W24: 0 | X24: 0 | Y24: 0 | Z24: 0 | AA24: 0 | AB24: 0 | AC24: 0 | AD24: 0 | AE24: 12 | AF24: 4
A25: B26 | B25: VC | C25: 2015 | D25: 14 | E25: Vegetation height | F25: 250 | G25: 250 | H25: 250 | I25: 250 | J25: 250 | K25: 250 | L25: 250 | M25: 250 | N25: 250 | O25: 250 | P25: 250 | Q25: 250 | R25: 250 | S25: 250 | T25: 250 | U25: 250 | V25: 250 | W25: 250 | X25: 250 | Y25: 250 | Z25: 250 | AA25: 250 | AB25: 250 | AC25: 250 | AD25: 250 | AG25: VEGETATION HEIGHT not measured on a cell by cell basis | AH25: DI900
A26: B26 | B26: VC | C26: 2015 | D26: 14 | E26: Bare soil | AE26: 12 | AF26: 0 | AG26: NO CELL DATA. ? Against plot no. | AH26: DI801 | AI26: DI990 | AK26: QA777 | AN26: QA777
A27: B26 | B27: VC | C27: 2015 | D27: 14 | E27: Litter | AE27: 90 | AF27: 0 | AG27: NO CELL DATA. ? Against plot no. | AH27: DI801 | AI27: DI990 | AK27: QA777 | AN27: QA777
A28: B26 | B28: VC | C28: 2015 | D28: 16 | E28: Vegetation height | F28: 5 | G28: 10 | H28: 19 | I28: 14 | J28: 9 | K28: 12 | L28: 7 | M28: 12 | N28: 5 | O28: 6 | P28: 6 | Q28: 6 | R28: 7 | S28: 9 | T28: 11 | U28: 12 | V28: 11 | W28: 5 | X28: 6 | Y28: 10 | Z28: 9 | AA28: 8 | AB28: 6 | AC28: 8 | AD28: 6
A29: B26 | B29: VC | C29: 2015 | D29: 16 | E29: Open water | F29: 0 | G29: 0 | H29: 0 | I29: 0 | J29: 0 | K29: 0 | L29: 0 | M29: 0 | N29: 0 | O29: 0 | P29: 0 | Q29: 0 | R29: 0 | S29: 0 | T29: 0 | U29: 0 | V29: 0 | W29: 0 | X29: 0 | Y29: 0 | Z29: 0 | AA29: 0 | AB29: 0 | AC29: 0 | AD29: 1 | AE29: 1 | AF29: 1
A30: B26 | B30: VC | C30: 2015 | D30: 16 | E30: Bare peat | F30: 1 | G30: 1 | H30: 0 | I30: 0 | J30: 1 | K30: 0 | L30: 1 | M30: 1 | N30: 1 | O30: 0 | P30: 1 | Q30: 0 | R30: 0 | S30: 0 | T30: 0 | U30: 1 | V30: 1 | W30: 1 | X30: 1 | Y30: 1 | Z30: 1 | AA30: 1 | AB30: 1 | AC30: 1 | AD30: 1 | AE30: 10 | AF30: 17
A31: B26 | B31: VC | C31: 2015 | D31: 18 | E31: Vegetation height | F31: 17 | G31: 24 | H31: 42 | I31: 37 | J31: 40 | K31: 20 | L31: 28 | M31: 34 | N31: 41 | O31: 52 | P31: 25 | Q31: 20 | R31: 20 | S31: 24 | T31: 38 | U31: 14 | V31: 18 | W31: 8 | X31: 8 | Y31: 20 | Z31: 21 | AA31: 15 | AB31: 6 | AC31: 14 | AD31: 34
A32: B26 | B32: VC | C32: 2015 | D32: 18 | E32: Litter | F32: 1 | G32: 1 | H32: 1 | I32: 1 | J32: 1 | K32: 1 | L32: 1 | M32: 1 | N32: 1 | O32: 1 | P32: 1 | Q32: 1 | R32: 1 | S32: 1 | T32: 1 | U32: 1 | V32: 1 | W32: 1 | X32: 1 | Y32: 1 | Z32: 1 | AA32: 1 | AB32: 1 | AC32: 1 | AD32: 1 | AE32: 90 | AF32: 25
A33: B26 | B33: VC | C33: 2015 | D33: 20 | E33: Vegetation height | F33: 4 | G33: 5 | H33: 7 | I33: 7 | J33: 2.5 | K33: 6 | L33: 9.5 | M33: 3.5 | N33: 3 | O33: 3.5 | P33: 9 | Q33: 3.5 | R33: 4 | S33: 6 | T33: 4.5 | U33: 4.5 | V33: 11.5 | W33: 7.5 | X33: 10.5 | Y33: 6.5 | Z33: 15 | AA33: 4.5 | AB33: 10 | AC33: 3 | AD33: 4.5
A34: B26 | B34: VC | C34: 2015 | D34: 20 | E34: Bare earth | F34: 1 | G34: 1 | H34: 1 | I34: 1 | J34: 1 | K34: 1 | L34: 1 | M34: 1 | N34: 1 | O34: 1 | P34: 1 | Q34: 1 | R34: 1 | S34: 1 | T34: 1 | U34: 1 | V34: 1 | W34: 1 | X34: 1 | Y34: 1 | Z34: 0 | AA34: 0 | AB34: 1 | AC34: 0 | AD34: 0 | AE34: 10 | AF34: 21
A35: B26 | B35: VC | C35: 2015 | D35: 20 | E35: Litter | F35: 1 | G35: 1 | H35: 1 | I35: 1 | J35: 1 | K35: 1 | L35: 1 | M35: 1 | N35: 1 | O35: 1 | P35: 1 | Q35: 1 | R35: 1 | S35: 1 | T35: 1 | U35: 1 | V35: 1 | W35: 1 | X35: 1 | Y35: 1 | Z35: 1 | AA35: 1 | AB35: 1 | AC35: 1 | AD35: 1 | AE35: 15 | AF35: 25
A36: B26 | B36: VC | C36: 2015 | D36: 20 | E36: Bare Rock | F36: 0 | G36: 0 | H36: 0 | I36: 0 | J36: 0 | K36: 0 | L36: 0 | M36: 0 | N36: 0 | O36: 0 | P36: 0 | Q36: 0 | R36: 0 | S36: 0 | T36: 0 | U36: 0 | V36: 0 | W36: 0 | X36: 0 | Y36: 0 | Z36: 0 | AA36: 0 | AB36: 0 | AC36: 0 | AD36: 1 | AE36: 0.1 | AF36: 1 | AG36: recorded as 'stone' - changed to bare rock. | AH36: DI805 | AI36: DI990 | AK36: QA600 | AL36: QA901 | AN36: QA901
A37: B26 | B37: VC | C37: 2015 | D37: 21 | E37: Vegetation height | F37: 21.5 | G37: 21.5 | H37: 15 | I37: 13 | J37: 21 | K37: 16 | L37: 22 | M37: 16 | N37: 20.5 | O37: 17.5 | P37: 9 | Q37: 19 | R37: 11 | S37: 19 | T37: 18 | U37: 14 | V37: 18 | W37: 19.5 | X37: 21 | Y37: 19 | Z37: 15 | AA37: 20.5 | AB37: 29 | AC37: 27 | AD37: 19
A38: B26 | B38: VC | C38: 2015 | D38: 21 | E38: Bare peat | F38: 0 | G38: 0 | H38: 0 | I38: 0 | J38: 0 | K38: 0 | L38: 0 | M38: 0 | N38: 0 | O38: 0 | P38: 0 | Q38: 0 | R38: 0 | S38: 0 | T38: 0 | U38: 0 | V38: 0 | W38: 0 | X38: 1 | Y38: 0 | Z38: 1 | AA38: 1 | AB38: 0 | AC38: 0 | AD38: 0 | AE38: 0.1 | AF38: 3
A39: B26 | B39: VC | C39: 2015 | D39: 21 | E39: Litter | F39: 1 | G39: 1 | H39: 1 | I39: 1 | J39: 1 | K39: 1 | L39: 1 | M39: 1 | N39: 1 | O39: 1 | P39: 1 | Q39: 1 | R39: 1 | S39: 1 | T39: 1 | U39: 1 | V39: 1 | W39: 1 | X39: 1 | Y39: 1 | Z39: 1 | AA39: 1 | AB39: 1 | AC39: 1 | AD39: 1 | AE39: 15 | AF39: 25
A40: B26 | B40: VC | C40: 2015 | D40: 24 | E40: Vegetation height | F40: 16 | G40: 10 | H40: 16 | I40: 16 | J40: 15 | K40: 13 | L40: 15 | M40: 10 | N40: 11 | O40: 14 | P40: 13 | Q40: 21 | R40: 14 | S40: 10 | T40: 7 | U40: 7 | V40: 19 | W40: 11 | X40: 16 | Y40: 10 | Z40: 10 | AA40: 14 | AB40: 17 | AC40: 12 | AD40: 22
...

Sheet Woodland Coordinates
A1: SITECODE | B1: MCODE | C1: YEAR | D1: PLOT_ID | E1: WOODLAND_SUBCELL_ID | F1: WOODLAND_SUBCELL_X | G1: WOODLAND_SUBCELL_Y | H1: BEARING_OF_STEM_FROM_CENTRE_OF_RANDOM_CELL | I1: DISTANCE_OF_STEM_FROM_CENTRE_OF_RANDOM_CELL | J1: DATA _ENTRY_COMMENTS | K1: DATA_ISSUE1 | L1: DATA_ISSUE2 | M1: DATA_ISSUE3 | N1: QA_CODE1 | O1: QA_CODE2 | P1: QA_CODE3 | Q1: FINAL_QA
A2: B26 | B2: VW | C2: 2015 | D2: 19 | E2: 1 | F2: 22 | G2: 24 | H2: 184 | J2: DISTANCE_OF_STEM_FROM_CENTRE_OF_RANDOM_CELL category added after this survey took place.
A3: B26 | B3: VW | C3: 2015 | D3: 19 | E3: 2 | F3: 12 | G3: 23 | H3: 112
A4: B26 | B4: VW | C4: 2015 | D4: 19 | E4: 3 | F4: 22 | G4: 25 | H4: 110
A5: B26 | B5: VW | C5: 2015 | D5: 19 | E5: 4 | F5: 4 | G5: 24 | H5: 0
A6: B26 | B6: VW | C6: 2015 | D6: 19 | E6: 5 | F6: 22 | G6: 4 | H6: 270
A7: B26 | B7: VW | C7: 2015 | D7: 19 | E7: 6 | F7: 6 | G7: 22 | H7: 320
A8: B26 | B8: VW | C8: 2015 | D8: 19 | E8: 7 | F8: 15 | G8: 9 | H8: 10
A9: B26 | B9: VW | C9: 2015 | D9: 19 | E9: 8 | F9: 23 | G9: 18 | H9: 220
A10: B26 | B10: VW | C10: 2015 | D10: 19 | E10: 9 | F10: 19 | G10: 23 | H10: 180
A11: B26 | B11: VW | C11: 2015 | D11: 19 | E11: 10 | F11: 21 | G11: 11 | H11: 270
A12: B26 | B12: VW | C12: 2015 | D12: 45 | E12: 1 | F12: 8 | G12: 3 | H12: 238
A13: B26 | B13: VW | C13: 2015 | D13: 45 | E13: 2 | F13: 5 | G13: 16 | H13: 249
A14: B26 | B14: VW | C14: 2015 | D14: 45 | E14: 3 | F14: 10 | G14: 10 | H14: 240
... A17: B26 | B17: VW | C17: 2015 | D17: 45 | E17: 6 | F17: 6 | G17: 20 | H17: 292
A18: B26 | B18: VW | C18: 2015 | D18: 45 | E18: 7 | F18: 16 | G18: 2 | J18: Tree dead | K18: 237
A19: B26 | B19: VW | C19: 2015 | D19: 45 | E19: 8 | F19: 21 | G19: 10 | H19: 351
A20: B26 | B20: VW | C20: 2015 | D20: 45 | E20: 9 | F20: 18 | G20: 8 | H20: 232
A21: B26 | B21: VW | C21: 2015 | D21: 45 | E21: 10 | F21: 2 | G21: 24 | H21: 230

Sheet Seedlings Template
A1: SITECODE | B1: MCODE | C1: YEAR | D1: PLOT_ID | E1: SPECIES_NO | F1: DESC_LATIN | G1: CELL_1 | H1: CELL_2 | I1: CELL_3 | J1: CELL_4 | K1: CELL_5 | L1: CELL_6 | M1: CELL_7 | N1: CELL_8 | O1: CELL_9 | P1: CELL_10 | Q1: DATA_ENTRY_COMMENTS | R1: DATA_ISSUE1 | S1: DATA_ISSUE2 | T1: DATA_ISSUE3 | U1: QA_CODE1 | V1: QA_CODE2 | W1: QA_CODE3 | X1: FINAL_QA
A2: B26 | B2: VW | C2: 2015 | D2: 19 | E2: 2634 | F2: Sorbus aucuparia (g) | G2: 1 | H2: 2 | I2: 0 | J2: 0 | K2: 0 | L2: 0 | M2: 2 | N2: 0 | O2: 0 | P2: 0

Sheet Tree Measurement
A1: SITECODE | B1: MCODE | C1: YEAR | D1: PLOT_ID | E1: CELL_ID | F1: TREE_ID | G1: STEM_ID | H1: SPECIES_NO | I1: DESC_LATIN | J1: GIRTH | K1: DIAMETER | L1: HEIGHT | M1: NUM_STEMS | N1: DISTANCE | O1: SURVEYOR_HEIGHT | P1: ANGLE | Q1: DATA_ENTRY_COMMENTS | R1: DATA_ISSUE1 | S1: DATA_ISSUE2 | T1: DATA_ISSUE3 | U1: QA_CODE1 | V1: QA_CODE2 | W1: QA_CODE3 | X1: FINAL_QA
A2: B26 | B2: VW | C2: 2015 | D2: 19 | E2: 1 | F2: 1 | H2: #N/A | I2: Betula pubscens hybrid | J2: 54 | K2: 17.188734 | L2: 26.858971 | M2: 1 | N2: 10.76 | O2: 1.51 | P2: 67 | Q2: Year "2015" not recorded, added later. Tree ID not recorded, so copied from stem ID later.
A3: B26 | B3: VW | C3: 2015 | D3: 19 | E3: 2 | F3: 2 | H3: #N/A | I3: Betula pubscens hybrid | J3: 38 | K3: 12.095776 | L3: 49.354352 | M3: 1 | N3: 9.3 | O3: 1.51 | P3: 79 | Q3: Year "2015" not recorded, added later. Tree ID not recorded, so copied from stem ID later.
A4: B26 | B4: VW | C4: 2015 | D4: 19 | E4: 3 | F4: 3 | H4: #N/A | I4: Betula pubscens hybrid | J4: 83 | K4: 26.419721 | L4: 23.523003 | M4: 1 | N4: 8.45 | O4: 1.51 | P4: 69 | Q4: Year "2015" not recorded, added later. Tree ID not recorded, so copied from stem ID later.
A5: B26 | B5: VW | C5: 2015 | D5: 19 | E5: 4 | F5: 4 | H5: 237 | I5: Betula pendula (c) | J5: 43 | K5: 13.687325 | L5: 23.902305 | M5: 1 | N5: 6 | O5: 1.51 | P5: 75 | Q5: Year "2015" not recorded, added later. Tree ID not recorded, so copied from stem ID later.
A6: B26 | B6: VW | C6: 2015 | D6: 19 | E6: 5 | F6: 5 | H6: #N/A | I6: Betula pendula hybrid | J6: 40 | K6: 12.732395 | L6: 16.844233 | M6: 1 | N6: 5.28 | O6: 1.51 | P6: 71 | Q6: Year "2015" not recorded, added later. Tree ID not recorded, so copied from stem ID later.
A7: B26 | B7: VW | C7: 2015 | D7: 19 | E7: 6 | F7: 6 | H7: #N/A | I7: Betula pendula hybrid | J7: 24 | K7: 7.6394373 | L7: 10.164253 | M7: 1 | N7: 5.2 | O7: 1.51 | P7: 59 | Q7: Year "2015" not recorded, added later. Tree ID not recorded, so copied from stem ID later.
A8: B26 | B8: VW | C8: 2015 | D8: 19 | E8: 7 | F8: 7 | H8: 1275 | I8: Sorbus aucuparia (c) | J8: 68 | K8: 21.645072 | L8: 10.003087 | M8: 1 | N8: 6.4 | O8: 1.51 | P8: 53 | Q8: Year "2015" not recorded, added later. Tree ID not recorded, so copied from stem ID later.
A9: B26 | B9: VW | C9: 2015 | D9: 19 | E9: 8 | F9: 8 | H9: #N/A | I9: Betula pubscens hybrid | J9: 33 | K9: 10.504226 | L9: 12.304358 | M9: 1 | N9: 5.5 | O9: 1.51 | P9: 63 | Q9: Year "2015" not recorded, added later. Tree ID not recorded, so copied from stem ID later.
A10: B26 | B10: VW | C10: 2015 | D10: 19 | E10: 9 | F10: 9 | H10: #N/A | I10: Betula pubscens hybrid | J10: 58 | K10: 18.461973 | L10: 21.08263 | M10: 1 | N10: 3.1 | O10: 1.51 | P10: 81 | Q10: Year "2015" not recorded, added later. Tree ID not recorded, so copied from stem ID later.
A11: B26 | B11: VW | C11: 2015 | D11: 19 | E11: 10 | F11: 10 | H11: #N/A | I11: Betula pubscens hybrid | J11: 54 | K11: 17.188734 | L11: 7.340252 | M11: 1 | N11: 3.1 | O11: 1.51 | P11: 62 | Q11: Year "2015" not recorded, added later. Tree ID not recorded, so copied from stem ID later.
A12: B26 | B12: VW | C12: 2015 | D12: 45 | E12: 1 | F12: 1 | H12: 237 | I12: Betula pendula (c) | J12: 21 | K12: 6.6845076 | L12: 10.646581 | M12: 1 | N12: 8.52 | O12: 1.51 | P12: 47 | Q12: Year "2015" not recorded, added later. Tree ID not recorded, so copied from stem ID later.
A13: B26 | B13: VW | C13: 2015 | D13: 45 | E13: 2 | F13: 2 | H13: #N/A | I13: Betula sp. | K13: 0 | L13: 1.51 | M13: 1 | O13: 1.51 | Q13: Tree dead. Girth, diameter, distance and angle not recorded. Year "2015" not recorded, added later. Tree ID not recorded, so copied from stem ID later. | R13: 237 | U13: QA607 | V13: QA610 | X13: QA607
A14: B26 | B14: VW | C14: 2015 | D14: 45 | E14: 3 | F14: 3 | H14: 236 | I14: Betula pubescens (c) | J14: 14 | K14: 4.4563384 | L14: 9.4947491 | M14: 1 | N14: 6.7 | O14: 1.51 | P14: 50 | Q14: Year "2015" not recorded, added later. Tree ID not recorded, so copied from stem ID later.
A15: B26 | B15: VW | C15: 2015 | D15: 45 | E15: 4 | F15: 4 | H15: 237 | I15: Betula pendula (c) | J15: 38 | K15: 12.095776 | L15: 16.005702 | M15: 5 | N15: 10.15 | O15: 1.51 | P15: 55 | Q15: Year "2015" not recorded, added later. Tree ID not recorded, so copied from stem ID later.
A16: B26 | B16: VW | C16: 2015 | D16: 45 | E16: 5 | F16: 5 | H16: 237 | I16: Betula pendula (c) | J16: 18 | K16: 5.729578 | L16: 9.0315723 | M16: 1 | N16: 4.7 | O16: 1.51 | P16: 58 | Q16: Year "2015" not recorded, added later. Tree ID not recorded, so copied from stem ID later.
A17: B26 | B17: VW | C17: 2015 | D17: 45 | E17: 6 | F17: 6 | H17: 237 | I17: Betula pendula (c) | J17: 34 | K17: 10.822536 | L17: 10.537487 | M17: 1 | N17: 4.8 | O17: 1.51 | P17: 62 | Q17: Year "2015" not recorded, added later. Tree ID not recorded, so copied from stem ID later.
A18: B26 | B18: VW | C18: 2015 | D18: 45 | E18: 7 | F18: 7 | H18: #N/A | I18: dead | K18: 0 | L18: 1.51 | M18: 1 | O18: 1.51 | Q18: Tree dead. Girth, diameter, distance and angle not recorded. Year "2015" not recorded, added later. Tree ID not recorded, so copied from stem ID later. | R18: 237 | U18: QA766 | V18: QA610 | X18: QA766
A19: B26 | B19: VW | C19: 2015 | D19: 45 | E19: 8 | F19: 8 | H19: 971 | I19: Pinus sylvestris (c) | J19: 46 | K19: 14.642255 | L19: 7.3407157 | M19: 1 | N19: 5.25 | O19: 1.51 | P19: 48 | Q19: Year "2015" not recorded, added later. Tree ID not recorded, so copied from stem ID later.
A20: B26 | B20: VW | C20: 2015 | D20: 45 | E20: 9 | F20: 9 | H20: 237 | I20: Betula pendula (c) | J20: 43 | K20: 13.687325 | L20: 14.377042 | M20: 1 | N20: 6 | O20: 1.51 | P20: 65 | Q20: Year "2015" not recorded, added later. Tree ID not recorded, so copied from stem ID later.
A21: B26 | B21: VW | C21: 2015 | D21: 45 | E21: 10 | F21: 10 | H21: 237 | I21: Betula pendula (c) | J21: 21 | K21: 6.6845076 | L21: 5.3508029 | M21: 1 | N21: 2.4 | O21: 1.51 | P21: 58 | Q21: Year "2015" not recorded, added later. Tree ID not recorded, so copied from stem ID later.
J22: =IF(K22="","", K22/PI()) | L22: =IF(OR(P22="", N22="", O22=""), "", TAN(P22*PI()/180)*N22 +O22)
J23: =IF(K23="","", K23/PI()) | L23: =IF(OR(P23="", N23="", O23=""), "", TAN(P23*PI()/180)*N23 +O23)
J24: =IF(K24="","", K24/PI()) | L24: =IF(OR(P24="", N24="", O24=""), "", TAN(P24*PI()/180)*N24 +O24)
J25: =IF(K25="","", K25/PI()) | L25: =IF(OR(P25="", N25="", O25=""), "", TAN(P25*PI()/180)*N25 +O25)
J26: =IF(K26="","", K26/PI()) | L26: =IF(OR(P26="", N26="", O26=""), "", TAN(P26*PI()/180)*N26 +O26)
J27: =IF(K27="","", K27/PI()) | L27: =IF(OR(P27="", N27="", O27=""), "", TAN(P27*PI()/180)*N27 +O27)
J28: =IF(K28="","", K28/PI()) | L28: =IF(OR(P28="", N28="", O28=""), "", TAN(P28*PI()/180)*N28 +O28)
J29: =IF(K29="","", K29/PI()) | L29: =IF(OR(P29="", N29="", O29=""), "", TAN(P29*PI()/180)*N29 +O29)
J30: =IF(K30="","", K30/PI()) | L30: =IF(OR(P30="", N30="", O30=""), "", TAN(P30*PI()/180)*N30 +O30)
J31: =IF(K31="","", K31/PI()) | L31: =IF(OR(P31="", N31="", O31=""), "", TAN(P31*PI()/180)*N31 +O31)
J32: =IF(K32="","", K32/PI()) | L32: =IF(OR(P32="", N32="", O32=""), "", TAN(P32*PI()/180)*N32 +O32)
J33: =IF(K33="","", K33/PI()) | L33: =IF(OR(P33="", N33="", O33=""), "", TAN(P33*PI()/180)*N33 +O33)
... J2000: =IF(K2000="","", K2000/PI()) | L2000: =IF(OR(P2000="", N2000="", O2000=""), "", TAN(P2000*PI()/180)*N2000 +O2000)

Sheet Dominance Template
A1: SITECODE | B1: MCODE | C1: YEAR | D1: PLOT_ID | E1: SPECIES_NO | F1: DESC_LATIN | G1: DOM_CODE | H1: DATA _ENTRY_COMMENTS | I1: DATA_ISSUE1 | J1: DATA_ISSUE2 | K1: DATA_ISSUE3 | L1: QA_CODE1 | M1: QA_CODE2 | N1: QA_CODE3 | O1: FINAL_QA
A2: B26 | B2: VW | C2: 2015 | D2: 19 | E2: 237 | F2: Betula pendula (c) | G2: Tree | H2: "Tree" not recognised DOM_CODE. | I2: DI900
A3: B26 | B3: VW | C3: 2015 | D3: 19 | E3: 237 | F3: Betula pendula (c) | G3: D
A4: B26 | B4: VW | C4: 2015 | D4: 19 | E4: 237 | F4: Betula pendula (c) | G4: S
A5: B26 | B5: VW | C5: 2015 | D5: 19 | E5: 237 | F5: Betula pendula (c) | G5: U
A6: B26 | B6: VW | C6: 2015 | D6: 19 | E6: 1078 | F6: Quercus robur (c) | G6: Tree | H6: "Tree" not recognised DOM_CODE. | I6: DI900
A7: B26 | B7: VW | C7: 2015 | D7: 19 | E7: 2627 | F7: Quercus robur (s) | G7: A
A8: B26 | B8: VW | C8: 2015 | D8: 19 | E8: 2628 | F8: Quercus robur (g) | G8: E
A9: B26 | B9: VW | C9: 2015 | D9: 19 | E9: 1078 | F9: Quercus robur (c) | G9: S
A10: B26 | B10: VW | C10: 2015 | D10: 19 | E10: 1275 | F10: Sorbus aucuparia (c) | G10: Tree | H10: "Tree" not recognised DOM_CODE. | I10: DI900
A11: B26 | B11: VW | C11: 2015 | D11: 19 | E11: 1275 | F11: Sorbus aucuparia (c) | G11: S
A12: B26 | B12: VW | C12: 2015 | D12: 19 | E12: 2634 | F12: Sorbus aucuparia (g) | G12: E
A13: B26 | B13: VW | C13: 2015 | D13: 19 | E13: 4392 | F13: Prunus | G13: E | H13: Idenitified to genus only. | I13: DI900 | L13: QA607 | O13: QA607
A14: B26 | B14: VW | C14: 2015 | D14: 19 | E14: 2616 | F14: Ilex aquifolium (g) | G14: E
A15: B26 | B15: VW | C15: 2015 | D15: 19 | E15: 2613 | F15: Fagus sylvatica (g) | G15: E
A16: B26 | B16: VW | C16: 2015 | D16: 45 | E16: 237 | F16: Betula pendula (c) | H16: DOM_CODE not recorded. | I16: DI900
A17: B26 | B17: VW | C17: 2015 | D17: 45 | E17: 237 | F17: Betula pendula (c) | G17: A
A18: B26 | B18: VW | C18: 2015 | D18: 45 | E18: 237 | F18: Betula pendula (c) | G18: C
A19: B26 | B19: VW | C19: 2015 | D19: 45 | E19: 237 | F19: Betula pendula (c) | G19: S
A20: B26 | B20: VW | C20: 2015 | D20: 45 | E20: 237 | F20: Betula pendula (c) | G20: I
A21: B26 | B21: VW | C21: 2015 | D21: 45 | E21: 237 | F21: Betula pendula (c) | G21: U
A22: B26 | B22: VW | C22: 2015 | D22: 45 | E22: 1363 | F22: Ulex europaeus (s) | G22: H
A23: B26 | B23: VW | C23: 2015 | D23: 45 | E23: 1363 | F23: Ulex europaeus (s) | G23: U
A24: B26 | B24: VW | C24: 2015 | D24: 45 | E24: 971 | F24: Pinus sylvestris (c) | H24: DOM_CODE not recorded. | I24: DI900
A25: B26 | B25: VW | C25: 2015 | D25: 45 | E25: 971 | F25: Pinus sylvestris (c) | G25: S
A26: B26 | B26: VW | C26: 2015 | D26: 45 | E26: 236 | F26: Betula pubescens (c) | G26: A
A27: B26 | B27: VW | C27: 2015 | D27: 45 | E27: 1275 | F27: Sorbus aucuparia (c) | G27: E
A28: B26 | B28: VW | C28: 2015 | D28: 45 | E28: 1275 | F28: Sorbus aucuparia (c) | G28: U
A29: B26 | B29: VW | C29: 2015 | D29: 45 | E29: 2740 | F29: Ilex aquifolium (c) | G29: E

Sheet Species List
A1: Bryophytes | B1: Ferns & Horsetails | C1: Grasses, Sedges & Rushes | D1: Herbs | E1: Lichens | F1: Trees & shrubs | G1: Algae | H1: Fungi
A2: Brachythecium rutabulum | B2: Dryopteris dilatata | C2: Agrostis capillaris | D2: Cerastium fontanum | E2: Cladonia cervicornis | F2: Betula pendula (c, g & s) | G2: Filamentous algae | H2: Scutula epicladonia
A3: Campylopus flexuosus | B3: Pteridium aquilinum | C3: Agrostis stolonifera | D3: Cirsium dissectum | E3: Cladonia crispata | F3: Betula pendula hybrid
A4: Campylopus introflexus | C4: Agrostis vinealis | D4: Cuscuta epithymum | E4: Cladonia diversa | F4: Betula pubescens (c & g)
A5: Cephalozia connivens | C5: Carex echinata | D5: Drosera intermedia | E5: Cladonia fimbriata | F5: Betula pubscens hybrid
A6: Dicranum scoparium | C6: Carex panicea | D6: Drosera rotundifolia | E6: Cladonia floerkeana | F6: Calluna vulgaris
